Workbook

Sheet TROPA 192 
G3: Estab. Faenador: Solemar Alimentaria S.A. | K3: RINDE | L3: =+M55 -> 0.56489565
G4: Matricula: 300 | K4: PROM. | L4: =+L55/D55 -> 216.54333
G5: Nº SENASA: 3986
C8: Usuario/Matarife: | E8: DOS DE FIERRO S.A | I8: Productor: | J8: LOGINPET SRL
C9: Matricula: | E9: 27345 | I9: Nº DTE: | J9: 31773562-6 | K9: Nº Guia: | L9: G-CHO26-02660
I10: Fecha Ing.: | J10: 46159 | K10: Hora: | L10: 0.5
D14: Fecha Faena: | E14: 46160 | K14: Cuartos | L14: Kg
C15: Nº Tropa: | E15: 192 | J15: VQ | K15: =+COUNTIF($G$24:$G$55,"VQ")*2 -> 0 | L15: =+SUMIF($G$25:$G$54,"VQ",$L$25:$L$54) -> 0
C16: Cantidad Cabeza: | E16: 30 | J16: NT | K16: =+COUNTIF($G$24:$G$55,"NT")*2 -> 60 | L16: =+SUMIF($G$25:$G$54,"NT",$L$25:$L$54) -> 6496.3
C17: Kg Vivo entrada: | E17: =+I55 -> 11500 | J17: NO | K17: =+COUNTIF($G$24:$G$55,"NO")*2 -> 0 | L17: =+SUMIF($G$25:$G$54,"NO",$L$25:$L$54) -> 0
C18: Kg 1/2 Res | E18: =+L55 -> 6496.3 | J18: TO | K18: =+COUNTIF($G$24:$G$55,"TO")*2 -> 0 | L18: =+SUMIF($G$25:$G$54,"TO",$L$25:$L$54) -> 0
C19: Rinde: | E19: =+M55 -> 0.56489565 | J19: VA | K19: =+COUNTIF($G$24:$G$55,"VA")*2 -> 0 | L19: =+SUMIF($G$25:$G$54,"VA",$L$25:$L$54) -> 0
C20: Promedio: | E20: =+L55/D55 -> 216.54333 | J20: MEJ | K20: =+COUNTIF($G$24:$G$55,"MEJ")*2 -> 0 | L20: =+SUMIF($G$25:$G$54,"MEJ",$L$25:$L$54) -> 0
C23: Nº GARRON | D23: Nº ANIMAL | E23: RAZA | F23: TIPO DE ANIMAL | H23: Nº CARAVANA | I23: KG ENTRADA | J23: KG 1/2 A | K23: KG 1/2 B | L23: TOTAL KG | M23: RINDE FAENA
F24: Denticion | G24: Clasificacion
C25: 1 | D25: 2 | E25: HE | F25: 2D - NT | G25: NT | H25: C718 | I25: 430 | J25: 121.9 | K25: 120.7 | L25: =+J25+K25 -> 242.6 | M25: =+L25/I25 -> 0.56418605
C26: 2 | D26: 8 | E26: AA | F26: 2D - NT | G26: NT | H26: N947 | I26: 407 | J26: 125.8 | K26: 125 | L26: =+J26+K26 -> 250.8 | M26: =+L26/I26 -> 0.61621622
C27: 3 | D27: 12 | E27: CA | F27: 2D - NT | G27: NT | H27: G810 | I27: 376 | J27: 111.2 | K27: 110.6 | L27: =+J27+K27 -> 221.8 | M27: =+L27/I27 -> 0.58989362
C28: 4 | D28: 10 | E28: HE | F28: 2D - NT | G28: NT | H28: C721 | I28: 384 | J28: 103.8 | K28: 104.1 | L28: =+J28+K28 -> 207.9 | M28: =+L28/I28 -> 0.54140625
C29: 5 | D29: 14 | E29: AA | F29: 2D - NT | G29: NT | H29: F586 | I29: 386 | J29: 111 | K29: 111.1 | L29: =+J29+K29 -> 222.1 | M29: =+L29/I29 -> 0.5753886
C30: 6 | D30: 4 | E30: CA | F30: 2D - NT | G30: NT | H30: G704 | I30: 375 | J30: 101.8 | K30: 102.3 | L30: =+J30+K30 -> 204.1 | M30: =+L30/I30 -> 0.54426667
C31: 7 | D31: 1 | E31: CA | F31: 2D - NT | G31: NT | H31: F534 | I31: 358 | J31: 103.9 | K31: 102.4 | L31: =+J31+K31 -> 206.3 | M31: =+L31/I31 -> 0.57625698
C32: 8 | D32: 6 | E32: HE | F32: 2D - NT | G32: NT | H32: S/C | I32: 375 | J32: 106.3 | K32: 105.6 | L32: =+J32+K32 -> 211.9 | M32: =+L32/I32 -> 0.56506667
C33: 9 | D33: 7 | E33: CA | F33: 2D - NT | G33: NT | H33: J027 | I33: 358 | J33: 103.1 | K33: 102.5 | L33: =+J33+K33 -> 205.6 | M33: =+L33/I33 -> 0.57430168
C34: 10 | D34: 9 | E34: HE | F34: 2D - NT | G34: NT | H34: K231 | I34: 375 | J34: 101.7 | K34: 101.2 | L34: =+J34+K34 -> 202.9 | M34: =+L34/I34 -> 0.54106667
C35: 11 | D35: 3 | E35: HE | F35: 2D - NT | G35: NT | H35: G018 | I35: 377 | J35: 108.7 | K35: 109.6 | L35: =+J35+K35 -> 218.3 | M35: =+L35/I35 -> 0.57904509
C36: 12 | D36: 5 | E36: CA | F36: 2D - NT | G36: NT | H36: G564 | I36: 365 | J36: 97.9 | K36: 98.8 | L36: =+J36+K36 -> 196.7 | M36: =+L36/I36 -> 0.53890411
... C54: 30 | D54: 22 | E54: AA | F54: 2D - NT | G54: NT | H54: A109 | I54: 483 | J54: 142.2 | K54: 141.8 | L54: =+J54+K54 -> 284 | M54: =+L54/I54 -> 0.58799172
D55: =+COUNT($D$24:$D$54) -> 30 | I55: =SUM($I$24:$I$54) -> 11500 | J55: =SUM($J$24:$J$54) -> 3249.8 | K55: =SUM($K$24:$K$54) -> 3246.5 | L55: =SUM($L$24:$L$54) -> 6496.3 | M55: =+L55/I55 -> 0.56489565
D59: MENUDENCIA | H59: Cantidades | I59: Kg | J59: Unidad | K59: Kg Dec.
D60: CHINCHULIN (KG)
D61: CORAZON
D62: HIGADO
D63: LENGUA
D64: MOLLEJAS (KG)
D65: RIÑON
D66: TENDON
D67: TRIPA GORDA
D68: CENTRO DE ENTRAÑA
D69: QUIJADA (KG)
...

Sheet TROPA 192  A PROVEEDOR
G3: Estab. Faenador: Solemar Alimentaria S.A. | K3: RINDE | L3: =+M55 -> 0.56124348
G4: Matricula: 300 | K4: PROM. | L4: =+L55/D55 -> 215.14333
G5: Nº SENASA: 3986
C8: Usuario/Matarife: | E8: DOS DE FIERRO S.A | I8: Productor: | J8: LOGINPET SRL
C9: Matricula: | E9: 27345 | I9: Nº DTE: | J9: 31773562-6 | K9: Nº Guia: | L9: G-CHO26-02660
I10: Fecha Ing.: | J10: 46159 | K10: Hora: | L10: 0.5
D14: Fecha Faena: | E14: 46160 | K14: Cuartos | L14: Kg
C15: Nº Tropa: | E15: 192 | J15: VQ | K15: =+COUNTIF($G$24:$G$55,"VQ")*2 -> 0 | L15: =+SUMIF($G$25:$G$54,"VQ",$L$25:$L$54) -> 0
C16: Cantidad Cabeza: | E16: 30 | J16: NT | K16: =+COUNTIF($G$24:$G$55,"NT")*2 -> 60 | L16: =+SUMIF($G$25:$G$54,"NT",$L$25:$L$54) -> 6454.3
C17: Kg Vivo entrada: | E17: =+I55 -> 11500 | J17: NO | K17: =+COUNTIF($G$24:$G$55,"NO")*2 -> 0 | L17: =+SUMIF($G$25:$G$54,"NO",$L$25:$L$54) -> 0
C18: Kg 1/2 Res | E18: =+L55 -> 6454.3 | J18: TO | K18: =+COUNTIF($G$24:$G$55,"TO")*2 -> 0 | L18: =+SUMIF($G$25:$G$54,"TO",$L$25:$L$54) -> 0
C19: Rinde: | E19: =+M55 -> 0.56124348 | J19: VA | K19: =+COUNTIF($G$24:$G$55,"VA")*2 -> 0 | L19: =+SUMIF($G$25:$G$54,"VA",$L$25:$L$54) -> 0
C20: Promedio: | E20: =+L55/D55 -> 215.14333 | J20: MEJ | K20: =+COUNTIF($G$24:$G$55,"MEJ")*2 -> 0 | L20: =+SUMIF($G$25:$G$54,"MEJ",$L$25:$L$54) -> 0
C23: Nº GARRON | D23: Nº ANIMAL | E23: RAZA | F23: TIPO DE ANIMAL | H23: Nº CARAVANA | I23: KG ENTRADA | J23: KG 1/2 A | K23: KG 1/2 B | L23: TOTAL KG | M23: RINDE FAENA
F24: Denticion | G24: Clasificacion
C25: 1 | D25: 2 | E25: HE | F25: 2D - NT | G25: NT | H25: C718 | I25: 430 | J25: =+'TROPA 192 '!J25-0.7 -> 121.2 | K25: =+'TROPA 192 '!K25-0.7 -> 120 | L25: =+J25+K25 -> 241.2 | M25: =+L25/I25 -> 0.56093023
C26: 2 | D26: 8 | E26: AA | F26: 2D - NT | G26: NT | H26: N947 | I26: 407 | J26: =+'TROPA 192 '!J26-0.7 -> 125.1 | K26: =+'TROPA 192 '!K26-0.7 -> 124.3 | L26: =+J26+K26 -> 249.4 | M26: =+L26/I26 -> 0.61277641
C27: 3 | D27: 12 | E27: CA | F27: 2D - NT | G27: NT | H27: G810 | I27: 376 | J27: =+'TROPA 192 '!J27-0.7 -> 110.5 | K27: =+'TROPA 192 '!K27-0.7 -> 109.9 | L27: =+J27+K27 -> 220.4 | M27: =+L27/I27 -> 0.58617021
C28: 4 | D28: 10 | E28: HE | F28: 2D - NT | G28: NT | H28: C721 | I28: 384 | J28: =+'TROPA 192 '!J28-0.7 -> 103.1 | K28: =+'TROPA 192 '!K28-0.7 -> 103.4 | L28: =+J28+K28 -> 206.5 | M28: =+L28/I28 -> 0.53776042
C29: 5 | D29: 14 | E29: AA | F29: 2D - NT | G29: NT | H29: F586 | I29: 386 | J29: =+'TROPA 192 '!J29-0.7 -> 110.3 | K29: =+'TROPA 192 '!K29-0.7 -> 110.4 | L29: =+J29+K29 -> 220.7 | M29: =+L29/I29 -> 0.57176166
C30: 6 | D30: 4 | E30: CA | F30: 2D - NT | G30: NT | H30: G704 | I30: 375 | J30: =+'TROPA 192 '!J30-0.7 -> 101.1 | K30: =+'TROPA 192 '!K30-0.7 -> 101.6 | L30: =+J30+K30 -> 202.7 | M30: =+L30/I30 -> 0.54053333
C31: 7 | D31: 1 | E31: CA | F31: 2D - NT | G31: NT | H31: F534 | I31: 358 | J31: =+'TROPA 192 '!J31-0.7 -> 103.2 | K31: =+'TROPA 192 '!K31-0.7 -> 101.7 | L31: =+J31+K31 -> 204.9 | M31: =+L31/I31 -> 0.57234637
C32: 8 | D32: 6 | E32: HE | F32: 2D - NT | G32: NT | H32: S/C | I32: 375 | J32: =+'TROPA 192 '!J32-0.7 -> 105.6 | K32: =+'TROPA 192 '!K32-0.7 -> 104.9 | L32: =+J32+K32 -> 210.5 | M32: =+L32/I32 -> 0.56133333
C33: 9 | D33: 7 | E33: CA | F33: 2D - NT | G33: NT | H33: J027 | I33: 358 | J33: =+'TROPA 192 '!J33-0.7 -> 102.4 | K33: =+'TROPA 192 '!K33-0.7 -> 101.8 | L33: =+J33+K33 -> 204.2 | M33: =+L33/I33 -> 0.57039106
C34: 10 | D34: 9 | E34: HE | F34: 2D - NT | G34: NT | H34: K231 | I34: 375 | J34: =+'TROPA 192 '!J34-0.7 -> 101 | K34: =+'TROPA 192 '!K34-0.7 -> 100.5 | L34: =+J34+K34 -> 201.5 | M34: =+L34/I34 -> 0.53733333
C35: 11 | D35: 3 | E35: HE | F35: 2D - NT | G35: NT | H35: G018 | I35: 377 | J35: =+'TROPA 192 '!J35-0.7 -> 108 | K35: =+'TROPA 192 '!K35-0.7 -> 108.9 | L35: =+J35+K35 -> 216.9 | M35: =+L35/I35 -> 0.57533156
C36: 12 | D36: 5 | E36: CA | F36: 2D - NT | G36: NT | H36: G564 | I36: 365 | J36: =+'TROPA 192 '!J36-0.7 -> 97.2 | K36: =+'TROPA 192 '!K36-0.7 -> 98.1 | L36: =+J36+K36 -> 195.3 | M36: =+L36/I36 -> 0.53506849
... C54: 30 | D54: 22 | E54: AA | F54: 2D - NT | G54: NT | H54: A109 | I54: 483 | J54: =+'TROPA 192 '!J54-0.7 -> 141.5 | K54: =+'TROPA 192 '!K54-0.7 -> 141.1 | L54: =+J54+K54 -> 282.6 | M54: =+L54/I54 -> 0.58509317
D55: =+COUNT($D$24:$D$54) -> 30 | I55: =SUM($I$24:$I$54) -> 11500 | J55: =SUM($J$24:$J$54) -> 3228.8 | K55: =SUM($K$24:$K$54) -> 3225.5 | L55: =SUM($L$24:$L$54) -> 6454.3 | M55: =+L55/I55 -> 0.56124348 | P55: =+'TROPA 192 '!L55 -> 6496.3
P56: =1.4*30 -> 42
P57: =+P55-P56 -> 6454.3
D59: MENUDENCIA | H59: Cantidades | I59: Kg | J59: Unidad | K59: Kg Dec.
D60: CHINCHULIN (KG)
D61: CORAZON
D62: HIGADO
D63: LENGUA
D64: MOLLEJAS (KG)
D65: RIÑON
D66: TENDON
D67: TRIPA GORDA
...

Sheet ROMANEO 1
E2: ROMANEO FAENA BOVINA
E3: FECHA: | F3: 46160
B4: N° GARRON | C4: TROPA | D4: TIPIFICACION | E4: KG 1/2 der | F4: KG 1/2 izq
B5: 1 | C5: 1 | D5: 2D - NT | E5: 121.9 | F5: 120.7
B6: =+B5+1 -> 2 | C6: 2 | D6: 2D - NT | E6: 125.8 | F6: 125
B7: =+B6+1 -> 3 | C7: 3 | D7: 2D - NT | E7: 111.2 | F7: 110.6
B8: =+B7+1 -> 4 | C8: 4 | D8: 2D - NT | E8: 103.8 | F8: 104.1
B9: =+B8+1 -> 5 | C9: 5 | D9: 2D - NT | E9: 111 | F9: 111.1
B10: =+B9+1 -> 6 | C10: 6 | D10: 2D - NT | E10: 101.8 | F10: 102.3
B11: =+B10+1 -> 7 | C11: 7 | D11: 2D - NT | E11: 103.9 | F11: 102.4
B12: =+B11+1 -> 8 | C12: 8 | D12: 2D - NT | E12: 106.3 | F12: 105.6
B13: =+B12+1 -> 9 | C13: 9 | D13: 2D - NT | E13: 103.1 | F13: 102.5
B14: =+B13+1 -> 10 | C14: 10 | D14: 2D - NT | E14: 101.7 | F14: 101.2
B15: =+B14+1 -> 11 | C15: 11 | D15: 2D - NT | E15: 108.7 | F15: 109.6
B16: =+B15+1 -> 12 | C16: 12 | D16: 2D - NT | E16: 97.9 | F16: 98.8
B17: =+B16+1 -> 13 | C17: 13 | D17: 2D - NT | E17: 103.6 | F17: 103.4
... B34: =+B33+1 -> 30 | C34: 30 | D34: 2D - NT | E34: 142.2 | F34: 141.8
B36: TROPA Nº | C36: CANTIDAD | D36: TIPO | E36: CANTIDAD | F36: TIPO
B37: 192 | C37: 30 | D37: NOVILLITO

Sheet denticion 1
E2: ROMANEO FAENA BOVINA
E3: FECHA: 18/05/2026
B4: N° CABEZA | C4: TROPA | D4: TIPIFICACION | E4: DIENTES
B5: 1 | C5: 192 | D5: 2D - NT
B6: =+B5+1 -> 2 | C6: 192 | D6: 2D - NT
B7: =+B6+1 -> 3 | C7: 192 | D7: 2D - NT
B8: =+B7+1 -> 4 | C8: 192 | D8: 2D - NT
B9: =+B8+1 -> 5 | C9: 192 | D9: 2D - NT
B10: =+B9+1 -> 6 | C10: 192 | D10: 2D - NT
B11: =+B10+1 -> 7 | C11: 192 | D11: 2D - NT
B12: =+B11+1 -> 8 | C12: 192 | D12: 2D - NT
B13: =+B12+1 -> 9 | C13: 192 | D13: 2D - NT
B14: =+B13+1 -> 10 | C14: 192 | D14: 2D - NT
B15: =+B14+1 -> 11 | C15: 192 | D15: 2D - NT
B16: =+B15+1 -> 12 | C16: 192 | D16: 2D - NT
B17: =+B16+1 -> 13 | C17: 192 | D17: 2D - NT
... B34: =+B33+1 -> 30 | C34: 192 | D34: 2D - NT

Sheet menudencias (1)
C1: FECHA: | D1: 46160
C2: TROPA: | D2: 192
C3: LOTE:
B4: USUARIO | C4: ARTICULO | D4: GUARDADO EN CAMARA | E4: ELABORADO KG | F4: BOLSAS
B5: DOS DE FIERRO S.A | C5: CHINCHULIN (KG) | D5: =22.6+24.44 -> 47.04 | E5: =15.54+16.36+13.58 -> 45.48 | F5: 3
C6: CORAZON | D6: 30 | E6: =23.4+25.02 -> 48.42 | F6: 2
C7: HIGADO | D7: 25 5 DECOMISOS 24.52KG | E7: =22.86+23.32+22.9+22.62+24.74 -> 116.44 | F7: 5
C8: LENGUA | D8: =17+13 -> 30 | E8: =16.6+16.66 -> 33.26 | F8: 2
C9: MOLLEJAS (KG) | D9: 22 | E9: 20.84 | F9: 1
C10: RIÑON | D10: 60 | E10: =13.08+12.98 -> 26.06 | F10: 2
C11: TENDON | D11: 120 | E11: 20.7 | F11: 1
C12: TRIPA GORDA | D12: 30 | E12: =14.92+14.16 -> 29.08 | F12: 2
C13: CENTRO DE ENTRAÑA | D13: 30 | E13: =11.98+11.58 -> 23.56 | F13: 2
C14: QUIJADA (KG) | D14: =25.2+15.26 -> 40.46 | E14: =14.3+23.82 -> 38.12 | F14: 2
C15: RABO | D15: 30 | E15: =13.78+13.44 -> 27.22 | F15: 2
C16: SESOS | D16: 30 | E16: =5.24+5.06 -> 10.3 | F16: 2
C17: CARNE DE CABEZA (KG) | D17: 11.08 | E17: 9.9 | F17: 1
D18: total | E18: =SUM(E5:E17) -> 449.38 | F18: =SUM(F5:F17) -> 27
B20: PESAJE INTERNO
B21: GRASA
B22: BOLSA AZUL | C22: 7.04
B24: CHINCHU - LAVADITO
B25: DESTINO | C25: USUARIO | D25: BOLSAS | E25: KG | F25: F. FAENA | G25: F. ELAB. | H25: F. VENC. | I25: TROPA
F26: 46097 | G26: =+F26+1 -> 46098 | H26: =+F26+5 -> 46102
D27: 6 | E27: =20+20.24+20.6+20.56+20.4+20.38 -> 122.18 | F27: 18/05/ | G27: =+F27+1 -> #VALUE! | H27: =+F27+5 -> #VALUE!
F28: 46099 | G28: =+F28+1 -> 46100 | H28: =+F28+5 -> 46104
F29: 46100 | G29: =+F29+1 -> 46101 | H29: =+F29+5 -> 46105
F30: 46101 | G30: =+F30+1 -> 46102 | H30: =+F30+5 -> 46106
